<?xml version="1.0" encoding="UTF-8"?>
<testsuite errors="1" failures="0" name="modelo.modelo_tests.TestDeposito-20160213192505" tests="1" time="0.031">
	<testcase classname="modelo.modelo_tests.TestDeposito" name="test1_save_try" time="0.031">
		<error message="'Deposito' object has no attribute 'dlt'" type="AttributeError">
<![CDATA[Traceback (most recent call last):
  File "/home/sebastian/proyectos/SiGeSt/src/unittest/python/modelo/modelo_tests.py", line 73, in test1_save_try
    self.depMock.dlt()
AttributeError: 'Deposito' object has no attribute 'dlt'
]]>		</error>
	</testcase>
	<system-out>
<![CDATA[]]>	</system-out>
	<system-err>
<![CDATA[]]>	</system-err>
</testsuite>
