<?xml version="1.0" encoding="UTF-8"?>
<testsuite errors="0" failures="2" name="modelo.modelo_tests.TestStock-20160214151124" tests="3" time="0.028">
	<testcase classname="modelo.modelo_tests.TestStock" name="test100_repr" time="0.001"/>
	<testcase classname="modelo.modelo_tests.TestStock" name="test1_save" time="0.018">
		<failure message="IntegrityError('(psycopg2.IntegrityError)[164 chars]\n',) != 'Error registrando el stock.'" type="AssertionError">
<![CDATA[Traceback (most recent call last):
  File "/home/sebastian/proyectos/SiGeSt/src/unittest/python/modelo/modelo_tests.py", line 124, in test1_save
    self.assertEqual(result, expected)
AssertionError: IntegrityError('(psycopg2.IntegrityError)[164 chars]\n',) != 'Error registrando el stock.'
]]>		</failure>
	</testcase>
	<testcase classname="modelo.modelo_tests.TestStock" name="test2_save" time="0.009">
		<failure message="IntegrityError('(psycopg2.IntegrityError)[164 chars]\n',) != 'Error registrando el stock.'" type="AssertionError">
<![CDATA[Traceback (most recent call last):
  File "/home/sebastian/proyectos/SiGeSt/src/unittest/python/modelo/modelo_tests.py", line 129, in test2_save
    self.assertEqual(result, expected)
AssertionError: IntegrityError('(psycopg2.IntegrityError)[164 chars]\n',) != 'Error registrando el stock.'
]]>		</failure>
	</testcase>
	<system-out>
<![CDATA[]]>	</system-out>
	<system-err>
<![CDATA[]]>	</system-err>
</testsuite>
