<?xml version="1.0" encoding="UTF-8"?>
<testsuite errors="0" failures="1" name="modelo.modelo_tests.TestMonolitico-20160213165929" tests="6" time="0.083">
	<testcase classname="modelo.modelo_tests.TestMonolitico" name="test1_save_try" time="0.030"/>
	<testcase classname="modelo.modelo_tests.TestMonolitico" name="test3_find" time="0.010"/>
	<testcase classname="modelo.modelo_tests.TestMonolitico" name="test4_dlt" time="0.028"/>
	<testcase classname="modelo.modelo_tests.TestMonolitico" name="test5_notfind" time="0.010"/>
	<testcase classname="modelo.modelo_tests.TestMonolitico" name="test6_repr" time="0.001"/>
	<testcase classname="modelo.modelo_tests.TestMonolitico" name="test2_save_try" time="0.004">
		<failure message="'El Articulo se inserto correctamente.' != 'Hubo un error en la insercion.'
- El Articulo se inserto correctamente.
+ Hubo un error en la insercion.
" type="AssertionError">
<![CDATA[Traceback (most recent call last):
  File "/home/sebastian/proyectos/SiGeSt/src/unittest/python/modelo/modelo_tests.py", line 51, in test2_save_try
    self.assertEqual(result, expected)
AssertionError: 'El Articulo se inserto correctamente.' != 'Hubo un error en la insercion.'
- El Articulo se inserto correctamente.
+ Hubo un error en la insercion.


Stdout:
Ejecutando test 2
]]>		</failure>
	</testcase>
	<system-out>
<![CDATA[Ejecutando test 2
Ejecutando test 4
Ejecutando test 5
Ejecutando test 6
Ejecutando test 2
]]>	</system-out>
	<system-err>
<![CDATA[]]>	</system-err>
</testsuite>
