<?xml version="1.0" encoding="UTF-8"?>
<testsuite errors="1" failures="1" name="modelo.modelo_tests.TestDeposito-20160213194010" tests="3" time="0.029">
	<testcase classname="modelo.modelo_tests.TestDeposito" name="test2_save_except" time="0.007"/>
	<testcase classname="modelo.modelo_tests.TestDeposito" name="test1_save_try" time="0.020">
		<failure message="'Error insertando el Deposito.' != 'El Deposito se inserto correctamente.'
- Error insertando el Deposito.
+ El Deposito se inserto correctamente.
" type="AssertionError">
<![CDATA[Traceback (most recent call last):
  File "/home/sebastian/proyectos/SiGeSt/src/unittest/python/modelo/modelo_tests.py", line 72, in test1_save_try
    self.assertEqual(result, expected)
AssertionError: 'Error insertando el Deposito.' != 'El Deposito se inserto correctamente.'
- Error insertando el Deposito.
+ El Deposito se inserto correctamente.

]]>		</failure>
	</testcase>
	<testcase classname="modelo.modelo_tests.TestDeposito" name="test3_find" time="0.002">
		<error message="name 'idDep' is not defined" type="NameError">
<![CDATA[Traceback (most recent call last):
  File "/home/sebastian/proyectos/SiGeSt/src/unittest/python/modelo/modelo_tests.py", line 81, in test3_find
    expected.id = idDep
NameError: name 'idDep' is not defined
]]>		</error>
	</testcase>
	<system-out>
<![CDATA[]]>	</system-out>
	<system-err>
<![CDATA[]]>	</system-err>
</testsuite>
