<?xml version="1.0" encoding="UTF-8"?>
<testsuite errors="0" failures="1" name="modelo.modelo_tests.TestFindMethods-20160213133402" tests="3" time="0.030">
	<testcase classname="modelo.modelo_tests.TestFindMethods" name="testrepr" time="0.001"/>
	<testcase classname="modelo.modelo_tests.TestFindMethods" name="testzfind" time="0.012"/>
	<testcase classname="modelo.modelo_tests.TestFindMethods" name="testsave" time="0.017">
		<failure message="None != 'El Articulo se inserto correctamente.'" type="AssertionError">
<![CDATA[Traceback (most recent call last):
  File "/home/sebastian/proyectos/SiGeSt/src/unittest/python/modelo/modelo_tests.py", line 19, in testsave
    'El Articulo se inserto correctamente.')
AssertionError: None != 'El Articulo se inserto correctamente.'
]]>		</failure>
	</testcase>
	<system-out>
<![CDATA[]]>	</system-out>
	<system-err>
<![CDATA[]]>	</system-err>
</testsuite>
