<?xml version="1.0" encoding="UTF-8"?>
<testsuite errors="0" failures="1" name="modelo.modelo_tests.TestDeposito-20160213195538" tests="4" time="0.054">
	<testcase classname="modelo.modelo_tests.TestDeposito" name="test1_save_try" time="0.020"/>
	<testcase classname="modelo.modelo_tests.TestDeposito" name="test2_save_except" time="0.010"/>
	<testcase classname="modelo.modelo_tests.TestDeposito" name="test3_find" time="0.013"/>
	<testcase classname="modelo.modelo_tests.TestDeposito" name="test3_notfind" time="0.011">
		<failure message="'No se encontro el deposito' != 'No se encontro'
- No se encontro el deposito
+ No se encontro
" type="AssertionError">
<![CDATA[Traceback (most recent call last):
  File "/home/sebastian/proyectos/SiGeSt/src/unittest/python/modelo/modelo_tests.py", line 88, in test3_notfind
    self.assertEqual(self.depMock.find('n'),'No se encontro')
AssertionError: 'No se encontro el deposito' != 'No se encontro'
- No se encontro el deposito
+ No se encontro

]]>		</failure>
	</testcase>
	<system-out>
<![CDATA[]]>	</system-out>
	<system-err>
<![CDATA[]]>	</system-err>
</testsuite>
