<?xml version="1.0" encoding="UTF-8"?>
<testsuite errors="0" failures="1" name="modelo.modelo_tests.TestArticulo-20160213195604" tests="7" time="0.119">
	<testcase classname="modelo.modelo_tests.TestArticulo" name="test1_save_try" time="0.049"/>
	<testcase classname="modelo.modelo_tests.TestArticulo" name="test2_save_except" time="0.009"/>
	<testcase classname="modelo.modelo_tests.TestArticulo" name="test3_find" time="0.012"/>
	<testcase classname="modelo.modelo_tests.TestArticulo" name="test4_dlt" time="0.033"/>
	<testcase classname="modelo.modelo_tests.TestArticulo" name="test4_dlt_except" time="0.002"/>
	<testcase classname="modelo.modelo_tests.TestArticulo" name="test6_repr" time="0.001"/>
	<testcase classname="modelo.modelo_tests.TestArticulo" name="test3_notfind" time="0.012">
		<failure message="Articulo('n', 'n') != 'No se encontro'" type="AssertionError">
<![CDATA[Traceback (most recent call last):
  File "/home/sebastian/proyectos/SiGeSt/src/unittest/python/modelo/modelo_tests.py", line 39, in test3_notfind
    self.assertEqual(self.artMock.find('n'),'No se encontro')
AssertionError: Articulo('n', 'n') != 'No se encontro'
]]>		</failure>
	</testcase>
	<system-out>
<![CDATA[]]>	</system-out>
	<system-err>
<![CDATA[]]>	</system-err>
</testsuite>
