<?xml version="1.0" encoding="UTF-8"?>
<testsuite errors="0" failures="1" name="modelo.modelo_tests.TestMonolitico-20160213175659" tests="7" time="0.227">
	<testcase classname="modelo.modelo_tests.TestMonolitico" name="test1_save_try" time="0.077"/>
	<testcase classname="modelo.modelo_tests.TestMonolitico" name="test2_save_except" time="0.007"/>
	<testcase classname="modelo.modelo_tests.TestMonolitico" name="test3_find" time="0.014"/>
	<testcase classname="modelo.modelo_tests.TestMonolitico" name="test4_dlt" time="0.111"/>
	<testcase classname="modelo.modelo_tests.TestMonolitico" name="test5_notfind" time="0.009"/>
	<testcase classname="modelo.modelo_tests.TestMonolitico" name="test6_repr" time="0.001"/>
	<testcase classname="modelo.modelo_tests.TestMonolitico" name="test4_dlt_except" time="0.009">
		<failure message="'Error eliminando' != 'Error eliminando.'
- Error eliminando
+ Error eliminando.
?                 +
" type="AssertionError">
<![CDATA[Traceback (most recent call last):
  File "/home/sebastian/proyectos/SiGeSt/src/unittest/python/modelo/modelo_tests.py", line 52, in test4_dlt_except
    self.assertEqual(result,expected)
AssertionError: 'Error eliminando' != 'Error eliminando.'
- Error eliminando
+ Error eliminando.
?                 +

]]>		</failure>
	</testcase>
	<system-out>
<![CDATA[]]>	</system-out>
	<system-err>
<![CDATA[]]>	</system-err>
</testsuite>
