<?xml version="1.0" encoding="UTF-8"?>
<testsuite errors="0" failures="1" name="modelo.modelo_tests.TestStock-20160214161155" tests="3" time="0.016">
	<testcase classname="modelo.modelo_tests.TestStock" name="test100_repr" time="0.001"/>
	<testcase classname="modelo.modelo_tests.TestStock" name="test1_save" time="0.012"/>
	<testcase classname="modelo.modelo_tests.TestStock" name="test2_findDep" time="0.003">
		<failure message="NameError(&quot;name 'stock' is not defined&quot;,) != 'Deposito'" type="AssertionError">
<![CDATA[Traceback (most recent call last):
  File "/home/sebastian/proyectos/SiGeSt/src/unittest/python/modelo/modelo_tests.py", line 129, in test2_findDep
    self.assertEqual(result, expected)
AssertionError: NameError("name 'stock' is not defined",) != 'Deposito'
]]>		</failure>
	</testcase>
	<system-out>
<![CDATA[]]>	</system-out>
	<system-err>
<![CDATA[]]>	</system-err>
</testsuite>
