<?xml version="1.0" encoding="UTF-8"?>
<testsuite errors="1" failures="0" name="modelo.modelo_tests.TestFindMethods-20160213101800" tests="1" time="0.004">
	<testcase classname="modelo.modelo_tests.TestFindMethods" name="testsave" time="0.004">
		<error message="name 'session' is not defined" type="NameError">
<![CDATA[Traceback (most recent call last):
  File "/home/sebastian/proyectos/SiGeSt/src/main/python/modelo/modelo.py", line 47, in save
    session.add(self)
NameError: name 'session' is not defined

During handling of the above exception, another exception occurred:

Traceback (most recent call last):
  File "/home/sebastian/proyectos/SiGeSt/src/main/python/modelo/modelo.py", line 51, in save
    session.rollback()
NameError: name 'session' is not defined

During handling of the above exception, another exception occurred:

Traceback (most recent call last):
  File "/home/sebastian/proyectos/SiGeSt/src/unittest/python/modelo/modelo_tests.py", line 18, in testsave
    self.assertEqual(self.artMock.save(),
  File "/home/sebastian/proyectos/SiGeSt/src/main/python/modelo/modelo.py", line 53, in save
    session.close()
NameError: name 'session' is not defined
]]>		</error>
	</testcase>
	<system-out>
<![CDATA[]]>	</system-out>
	<system-err>
<![CDATA[]]>	</system-err>
</testsuite>
