<?xml version="1.0" encoding="UTF-8"?>
<testsuite errors="0" failures="1" name="modelo.modelo_tests.TestFindMethods-20160213131824" tests="3" time="0.091">
	<testcase classname="modelo.modelo_tests.TestFindMethods" name="testfind" time="0.087"/>
	<testcase classname="modelo.modelo_tests.TestFindMethods" name="testrepr" time="0.001"/>
	<testcase classname="modelo.modelo_tests.TestFindMethods" name="testsave" time="0.003">
		<failure message="None != 'El Articulo se inserto correctamente.'" type="AssertionError">
<![CDATA[Traceback (most recent call last):
  File "/home/sebastian/proyectos/SiGeSt/src/unittest/python/modelo/modelo_tests.py", line 18, in testsave
    self.assertEqual(self.artMock.save(), 'El Articulo se inserto correctamente.')
AssertionError: None != 'El Articulo se inserto correctamente.'
]]>		</failure>
	</testcase>
	<system-out>
<![CDATA[]]>	</system-out>
	<system-err>
<![CDATA[]]>	</system-err>
</testsuite>
