<?xml version="1.0" encoding="UTF-8"?>
<testsuite errors="0" failures="1" name="modelo.modelo_tests.TestDeposito-20160213192331" tests="1" time="0.016">
	<testcase classname="modelo.modelo_tests.TestDeposito" name="test1_save_try" time="0.016">
		<failure message="('Error insertando el Deposito: ', &lt;class 'sqlalchemy.exc.IntegrityError'&gt;) != 'El Deposito se inserto correctamente.'" type="AssertionError">
<![CDATA[Traceback (most recent call last):
  File "/home/sebastian/proyectos/SiGeSt/src/unittest/python/modelo/modelo_tests.py", line 72, in test1_save_try
    self.assertEqual(result, expected)
AssertionError: ('Error insertando el Deposito: ', <class 'sqlalchemy.exc.IntegrityError'>) != 'El Deposito se inserto correctamente.'
]]>		</failure>
	</testcase>
	<system-out>
<![CDATA[]]>	</system-out>
	<system-err>
<![CDATA[]]>	</system-err>
</testsuite>
