<?xml version="1.0" encoding="UTF-8"?>
<testsuite errors="0" failures="2" name="modelo.modelo_tests.TestFindMethods-20160213103428" tests="3" time="0.048">
	<testcase classname="modelo.modelo_tests.TestFindMethods" name="testrepr" time="0.001"/>
	<testcase classname="modelo.modelo_tests.TestFindMethods" name="testfind" time="0.033">
		<failure message="Articulo('n', 'n') != Articulo('n', 'n')" type="AssertionError">
<![CDATA[Traceback (most recent call last):
  File "/home/sebastian/proyectos/SiGeSt/src/unittest/python/modelo/modelo_tests.py", line 31, in testfind
    self.assertEqual(self.artMock.find(self.idArt), result)
AssertionError: Articulo('n', 'n') != Articulo('n', 'n')
]]>		</failure>
	</testcase>
	<testcase classname="modelo.modelo_tests.TestFindMethods" name="testsave" time="0.014">
		<failure message="None != 'El Articulo se inserto correctamente.'" type="AssertionError">
<![CDATA[Traceback (most recent call last):
  File "/home/sebastian/proyectos/SiGeSt/src/unittest/python/modelo/modelo_tests.py", line 19, in testsave
    'El Articulo se inserto correctamente.')
AssertionError: None != 'El Articulo se inserto correctamente.'
]]>		</failure>
	</testcase>
	<system-out>
<![CDATA[]]>	</system-out>
	<system-err>
<![CDATA[]]>	</system-err>
</testsuite>
