<?xml version="1.0" encoding="UTF-8"?>
<testsuite errors="0" failures="1" name="modelo.modelo_tests.TestArticulo-20160214172838" tests="8" time="0.195">
	<testcase classname="modelo.modelo_tests.TestArticulo" name="test1_save_try" time="0.045"/>
	<testcase classname="modelo.modelo_tests.TestArticulo" name="test2_save_except" time="0.007"/>
	<testcase classname="modelo.modelo_tests.TestArticulo" name="test3_find" time="0.019"/>
	<testcase classname="modelo.modelo_tests.TestArticulo" name="test3_notfind" time="0.011"/>
	<testcase classname="modelo.modelo_tests.TestArticulo" name="test4_dlt" time="0.026"/>
	<testcase classname="modelo.modelo_tests.TestArticulo" name="test4_dlt_except" time="0.001"/>
	<testcase classname="modelo.modelo_tests.TestArticulo" name="test5_repr" time="0.001"/>
	<testcase classname="modelo.modelo_tests.TestArticulo" name="test0_find_mock" time="0.084">
		<failure message="'El Articulo se inserto correctamente.' != &lt;MagicMock name='mock.save()' id='3049079244'&gt;" type="AssertionError">
<![CDATA[Traceback (most recent call last):
  File "/home/sebastian/proyectos/SiGeSt/src/unittest/python/modelo/modelo_tests.py", line 22, in test0_find_mock
    self.assertEqual(expect, result)
AssertionError: 'El Articulo se inserto correctamente.' != <MagicMock name='mock.save()' id='3049079244'>
]]>		</failure>
	</testcase>
	<system-out>
<![CDATA[]]>	</system-out>
	<system-err>
<![CDATA[]]>	</system-err>
</testsuite>
