<?xml version="1.0" encoding="UTF-8"?>
<testsuite errors="1" failures="0" name="modelo.modelo_tests.TestDeposito-20160213194035" tests="3" time="0.035">
	<testcase classname="modelo.modelo_tests.TestDeposito" name="test1_save_try" time="0.020"/>
	<testcase classname="modelo.modelo_tests.TestDeposito" name="test2_save_except" time="0.011"/>
	<testcase classname="modelo.modelo_tests.TestDeposito" name="test3_find" time="0.004">
		<error message="name 'idDep' is not defined" type="NameError">
<![CDATA[Traceback (most recent call last):
  File "/home/sebastian/proyectos/SiGeSt/src/unittest/python/modelo/modelo_tests.py", line 81, in test3_find
    expected.id = idDep
NameError: name 'idDep' is not defined
]]>		</error>
	</testcase>
	<system-out>
<![CDATA[]]>	</system-out>
	<system-err>
<![CDATA[]]>	</system-err>
</testsuite>
