<?xml version="1.0" encoding="UTF-8"?>
<testsuite errors="0" failures="1" name="modelo.modelo_tests.TestStock-20160214172838" tests="3" time="0.022">
	<testcase classname="modelo.modelo_tests.TestStock" name="test100_repr" time="0.001"/>
	<testcase classname="modelo.modelo_tests.TestStock" name="test1_save" time="0.017"/>
	<testcase classname="modelo.modelo_tests.TestStock" name="test2_findDep" time="0.004">
		<failure message="&lt;sqlalchemy.orm.query.Query object at 0xb5ba6b8c&gt; != 'Deposito'" type="AssertionError">
<![CDATA[Traceback (most recent call last):
  File "/home/sebastian/proyectos/SiGeSt/src/unittest/python/modelo/modelo_tests.py", line 132, in test2_findDep
    self.assertEqual(result, expected)
AssertionError: <sqlalchemy.orm.query.Query object at 0xb5ba6b8c> != 'Deposito'
]]>		</failure>
	</testcase>
	<system-out>
<![CDATA[]]>	</system-out>
	<system-err>
<![CDATA[]]>	</system-err>
</testsuite>
