<?xml version="1.0" encoding="UTF-8"?>
<testsuite errors="1" failures="0" name="modelo.modelo_tests.TestMonolitico-20160213164403" tests="6" time="0.128">
	<testcase classname="modelo.modelo_tests.TestMonolitico" name="test1_save_try" time="0.060"/>
	<testcase classname="modelo.modelo_tests.TestMonolitico" name="test2_find" time="0.012"/>
	<testcase classname="modelo.modelo_tests.TestMonolitico" name="test3_dlt" time="0.042"/>
	<testcase classname="modelo.modelo_tests.TestMonolitico" name="test4_notfind" time="0.012"/>
	<testcase classname="modelo.modelo_tests.TestMonolitico" name="testrepr" time="0.001"/>
	<testcase classname="modelo.modelo_tests.TestMonolitico" name="test1_save_except" time="0.002">
		<error message="save() takes 1 positional argument but 2 were given" type="TypeError">
<![CDATA[Traceback (most recent call last):
  File "/home/sebastian/proyectos/SiGeSt/src/unittest/python/modelo/modelo_tests.py", line 42, in test1_save_except
    result = self.artMock.save(1)
TypeError: save() takes 1 positional argument but 2 were given
]]>		</error>
	</testcase>
	<system-out>
<![CDATA[]]>	</system-out>
	<system-err>
<![CDATA[]]>	</system-err>
</testsuite>
