<?xml version="1.0" encoding="UTF-8"?>
<testsuite errors="0" failures="2" name="modelo.modelo_tests.TestStock-20160214151029" tests="3" time="0.030">
	<testcase classname="modelo.modelo_tests.TestStock" name="test100_repr" time="0.001"/>
	<testcase classname="modelo.modelo_tests.TestStock" name="test1_save" time="0.021">
		<failure message="(&lt;class 'sqlalchemy.exc.IntegrityError'&gt;,[241 chars]c5c&gt;) != 'Error registrando el stock.'" type="AssertionError">
<![CDATA[Traceback (most recent call last):
  File "/home/sebastian/proyectos/SiGeSt/src/unittest/python/modelo/modelo_tests.py", line 124, in test1_save
    self.assertEqual(result, expected)
AssertionError: (<class 'sqlalchemy.exc.IntegrityError'>,[241 chars]c5c>) != 'Error registrando el stock.'
]]>		</failure>
	</testcase>
	<testcase classname="modelo.modelo_tests.TestStock" name="test2_save" time="0.008">
		<failure message="(&lt;class 'sqlalchemy.exc.IntegrityError'&gt;,[241 chars]2ac&gt;) != 'Error registrando el stock.'" type="AssertionError">
<![CDATA[Traceback (most recent call last):
  File "/home/sebastian/proyectos/SiGeSt/src/unittest/python/modelo/modelo_tests.py", line 129, in test2_save
    self.assertEqual(result, expected)
AssertionError: (<class 'sqlalchemy.exc.IntegrityError'>,[241 chars]2ac>) != 'Error registrando el stock.'
]]>		</failure>
	</testcase>
	<system-out>
<![CDATA[]]>	</system-out>
	<system-err>
<![CDATA[]]>	</system-err>
</testsuite>
