<?xml version="1.0" encoding="UTF-8"?>
<testsuite errors="0" failures="2" name="modelo.modelo_tests.TestDeposito-20160213195011" tests="3" time="0.032">
	<testcase classname="modelo.modelo_tests.TestDeposito" name="test2_save_except" time="0.006"/>
	<testcase classname="modelo.modelo_tests.TestDeposito" name="test1_save_try" time="0.017">
		<failure message="'Error insertando el Deposito.' != 'El Deposito se inserto correctamente.'
- Error insertando el Deposito.
+ El Deposito se inserto correctamente.
" type="AssertionError">
<![CDATA[Traceback (most recent call last):
  File "/home/sebastian/proyectos/SiGeSt/src/unittest/python/modelo/modelo_tests.py", line 72, in test1_save_try
    self.assertEqual(result, expected)
AssertionError: 'Error insertando el Deposito.' != 'El Deposito se inserto correctamente.'
- Error insertando el Deposito.
+ El Deposito se inserto correctamente.

]]>		</failure>
	</testcase>
	<testcase classname="modelo.modelo_tests.TestDeposito" name="test3_find" time="0.009">
		<failure message="'No se encontro el deposito' != Deposito('descrip deposito')" type="AssertionError">
<![CDATA[Traceback (most recent call last):
  File "/home/sebastian/proyectos/SiGeSt/src/unittest/python/modelo/modelo_tests.py", line 84, in test3_find
    self.assertEqual(result, expected)
AssertionError: 'No se encontro el deposito' != Deposito('descrip deposito')
]]>		</failure>
	</testcase>
	<system-out>
<![CDATA[]]>	</system-out>
	<system-err>
<![CDATA[]]>	</system-err>
</testsuite>
