<?xml version="1.0" encoding="UTF-8"?>
<testsuite errors="1" failures="0" name="modelo.modelo_tests.TestDeposito-20160213192222" tests="1" time="0.005">
	<testcase classname="modelo.modelo_tests.TestDeposito" name="test1_save_try" time="0.005">
		<error message="name 'sessionDep' is not defined" type="NameError">
<![CDATA[Traceback (most recent call last):
  File "/home/sebastian/proyectos/SiGeSt/src/main/python/modelo/modelo.py", line 89, in save
    sessionDep.add(self)
NameError: name 'sessionDep' is not defined

During handling of the above exception, another exception occurred:

Traceback (most recent call last):
  File "/home/sebastian/proyectos/SiGeSt/src/main/python/modelo/modelo.py", line 93, in save
    sessionDep.rollback()
NameError: name 'sessionDep' is not defined

During handling of the above exception, another exception occurred:

Traceback (most recent call last):
  File "/home/sebastian/proyectos/SiGeSt/src/unittest/python/modelo/modelo_tests.py", line 71, in test1_save_try
    result = self.depMock.save()
  File "/home/sebastian/proyectos/SiGeSt/src/main/python/modelo/modelo.py", line 96, in save
    sessionDep.close()
NameError: name 'sessionDep' is not defined
]]>		</error>
	</testcase>
	<system-out>
<![CDATA[]]>	</system-out>
	<system-err>
<![CDATA[]]>	</system-err>
</testsuite>
